Workbook
Name _Títulos_a_imprimir: Ofertas!$22:$22
Name aaa: #REF!
Name aaa: #REF!
Name GG: #REF!
Name GG: #REF!
Name OLE_LINK1: Ofertas!#REF!

Sheet Hoja2
A2: Año | B2: (Todas)
A3: Estado | B3: PG
A5: Etiquetas de fila | B5: Suma de Monto (M$) | C5: Suma de Horas Lic (hh)
A6: ACOTEC | B6: 1.5135 | C6: 41
A7: AF | B7: 0.8436 | C7: 22
A8: OS | B8: 0.6699 | C8: 19
A9: ALQUIMIA CONCEPTOS | B9: 76.226368 | C9: 2582
A10: IB | B10: 42.493848 | C10: 1341
A11: IC | B11: 19.608597 | C11: 695
A12: ID | B12: 8.085696 | C12: 309
A13: IP | B13: 5.554227 | C13: 207
A14: OS | B14: 0.484 | C14: 30
A15: Amec | B15: 6.5875 | C15: 155
A16: AT | B16: 6.5875 | C16: 155
A17: Anglo American | B17: 376.3785 | C17: 9883
... A41: ED | B41: 1.822 | C41: 75
A42: AO
A43: ASISTEP | B43: 0.1 | C43: 15
A44: PEM | B44: 0.1 | C44: 15
A45: Atacama Kozan | B45: 2.275 | C45: 95
A46: (en blanco) | B46: 2.275 | C46: 95
A47: Ausenco Brasil | B47: 50.52 | C47: 690
A48: AP | B48: 50.52 | C48: 690
A49: ID
A50: AUSENCO Chile | B50: 1.29276 | C50: 21
A51: CC | B51: 1.29276 | C51: 21
A52: AP
A53: BAS Concesionaria | B53: 5.92 | C53: 200
A54: ED | B54: 4.92 | C54: 150
A55: IB | B55: 1 | C55: 50
A56: BHP BILLITON | B56: 353.13229 | C56: 5511
A57: AO | B57: 214.72468 | C57: 3421
A58: ID | B58: 101.02813 | C58: 1250
A59: (en blanco) | B59: 37.379476 | C59: 840
A60: CANDELARIA | B60: 214.71088 | C60: 5867
A61: IB | B61: 152.63088 | C61: 4156
A62: IC | B62: 36.455 | C62: 1036
A63: ID | B63: 25.625 | C63: 675
A64: CAP Mineria | B64: 1087.8526 | C64: 27953
... A67: IC/IB/ID | B67: 85.306 | C67: 2097
...

Sheet Ofertas
C1: LISTADO DE PROPUESTAS AL | O1: TIPO DE NEGOCIACIÓN
C2: =NOW() -> 46090.713 | O2: ND | P2: Negociación Directa
E3: m2 | O3: LM | P3: Licitación Múltiple
O4: AC | P4: Apoyo Contratos | T4: Hoy | V4: =+TODAY() -> 46090
C5: TIPO DE SERVICIO | O5: LC | P5: Licitación Contrato Abierto | T5: Año anterior | V5: 40543
C6: IP/IC | D6: Proyecto T: Ingeniería de Perfil / Conceptual (Prefactibilidad) | O6: N/A | P6: No Aplica | T6: Dias | V6: =-V4+V5 -> -5547
C7: IB/ID/CO | D7: Proyecto P: Ingeniería Básica / de Detalle / de Contraparte | O7: ÁMBITO
C8: CC | D8: Proyecto D: Comisiones de Confianza, Auditoría, Estudio Estratégico, Diagnóstico, Benchmarking y Bases | O8: NAC | P8: Nacional
C9: EP(CM/C) | D9: Proyecto P: Ingeniería de Detalle, Adquisición y (Adm. Construcción / Construcción) | O9: INT | P9: Internacional
C10: AD | D10: Proyecto P: Adquisiciones | O10: ESTADO
C11: CA | D11: Proyecto F: Contratos Abiertos. Contrato Marco y Servicio de Asesoría | O11: PDS | P11: Por Definir Situación
C12: IT/AO/AC | D12: Proyecto S: Ingeniería de Terreno / Apoyo a Operaciones, Manual de Op. y Mant. y PEM / Adm. Construcción | O12: EP | P12: En Preparación
C13: TP | D13: Proyecto G: Transferencia de Profesionales | O13: NL | P13: Propuesta No Licitada
C14: CT | D14: Proyecto C: Capacitación a Terceros. Cursos, Seminarios, Talleres y Manuales | O14: DP | P14: Decisión del Cliente Pendiente
C15: VD | D15: Proyecto Q: Venta de Dragas y Elementos Relacionados | O15: PG | P15: Propuesta Ganada
C16: PR | D16: Precalificación, Inscripción y Registro. REGIC, SICEP | O16: PP | P16: Propuesta Perdida
C17: OS | D17: Otros Servicios | O17: PD | P17: Propuesta Declarada Desierta
O18: N/A | P18: No Aplica
V19: =+SUMIF(T:T,"DP",#REF!) -> #REF!
A22: Número Proyecto | B22: Numero | C22: Código Prop. | D22: Fecha Recep. | E22: Cliente | F22: Cliente Final | G22: Contacto | H22: Email | I22: Título | K22: Tipo Serv. | L22: Tipo Licitación | M22: Ámbito | N22: País | O22: Fecha Entrega | P22: Líder Técnico | Q22: Unidad de Negocio (antigua) | R22: Unidad de Negocio (Nueva) | S22: Comentario | T22: Estado | U22: Probabilidad | V22: Fecha Estado | W22: Horas Lic (hh) | X22: Monto (M$) | Y22: Tarifa Promedio | Z22: Razón propuesta perdida | AA22: Comentarios propuesta perdida o ganada | AB22: Código Proy. | AC22: Fecha de Inicio | AD22: Duración Servicio | AE22: Coord. | AF22: Seguimiento (Consultar) | AG22: Año | AH22: 2026 | AI22: 2025 | AJ22: 2024 | AK22: 2023 | AL22: 2022 | AM22: 2021 | AN22: 2020 | AO22: 2019 | AP22: 2018 | AQ22: 2017 | AR22: 2016 | AS22: 2015 | AT22: 2014 | AU22: 2013 | AV22: 2012 | AW22: 2011 | AX22: 2010 | AY22: A | AZ22: B | BA22: C | BB22: D | BC22: E | BD22: F | BE22: G | BF22: H
A23: =+IFERROR(VALUE(MID(AB23,4,4)),"") | B23: =VALUE(RIGHT(C23,LEN(C23)-2)) -> 2699 | C23: O-2699 | D23: 46084 | E23: Codelco | F23: DRT | G23: ARIBA | H23: ARIBA | I23: CM Planificación Minera Largo Plazo | K23: CM | L23: LM | M23: NAC | N23: #VALUE! | O23: 46104 | P23: TBD | Q23: CM | R23: CM | T23: NL | V23: 46085 | Y23: =IF(SUM(W23:W23)>0,X23/SUM(W23:W23)*1000000,"N/A") -> N/A | AG23: =YEAR(V23) -> 2026 | AH23: =+IF(AG23=$AH$22,MONTH(V23),"") -> 3 | AI23: =+IF(AG23=$AI$22,MONTH(V23),"") | AJ23: =+IF(AG23=$AJ$22,MONTH(V23),"") | AK23: =+IF(AG23=$AK$22,MONTH(V23),"") | AL23: =+IF(AG23=$AL$22,MONTH(V23),"") | AM23: =+IF($AG23=$AM$22,MONTH($D23),"") | AN23: =+IF($AG23=AN$22,MONTH($D23),"") | AO23: =+IF($AG23=AO$22,MONTH($D23),"") | AP23: =+IF($AG23=AP$22,MONTH($D23),"") | AQ23: =+IF($AG23=AQ$22,MONTH($D23),"") | AR23: =+IF($AG23=AR$22,MONTH($D23),"") | AS23: =+IF($AG23=AS$22,MONTH($D23),"") | AT23: =+IF($AG23=AT$22,MONTH($D23),"") | AU23: =+IF($AG23=AU$22,MONTH($D23),"") | ... AX23: =+IF($AG23=AX$22,MONTH($D23),"")
A24: =+IFERROR(VALUE(MID(AB24,4,4)),"") | B24: =VALUE(RIGHT(C24,LEN(C24)-2)) -> 2698 | C24: O-2698 | D24: 46085 | E24: Vale | F24: Vale | G24: Cassio Dayrell | H24: cassio.dayrell@vale.com | I24: ID Sistema de Selagem Rejeitoduto Lama - VGR-01 - VALE | K24: ID | L24: LC | M24: INT | N24: #VALUE! | O24: 46090 | P24: Gustavo Assis | Q24: TA | R24: RELAVES | T24: EP | V24: 46085 | Y24: =IF(SUM(W24:W24)>0,X24/SUM(W24:W24)*1000000,"N/A") -> N/A | AG24: =YEAR(V24) -> 2026 | AH24: =+IF(AG24=$AH$22,MONTH(V24),"") -> 3 | AI24: =+IF(AG24=$AI$22,MONTH(V24),"") | AJ24: =+IF(AG24=$AJ$22,MONTH(V24),"") | AK24: =+IF(AG24=$AK$22,MONTH(V24),"") | AL24: =+IF(AG24=$AL$22,MONTH(V24),"") | AM24: =+IF($AG24=$AM$22,MONTH($D24),"") | AN24: =+IF($AG24=AN$22,MONTH($D24),"") | AO24: =+IF($AG24=AO$22,MONTH($D24),"") | AP24: =+IF($AG24=AP$22,MONTH($D24),"") | AQ24: =+IF($AG24=AQ$22,MONTH($D24),"") | AR24: =+IF($AG24=AR$22,MONTH($D24),"") | AS24: =+IF($AG24=AS$22,MONTH($D24),"") | AT24: =+IF($AG24=AT$22,MONTH($D24),"") | AU24: =+IF($AG24=AU$22,MONTH($D24),"") | ... AX24: =+IF($AG24=AX$22,MONTH($D24),"")
A25: =+IFERROR(VALUE(MID(AB25,4,4)),"") | B25: =VALUE(RIGHT(C25,LEN(C25)-2)) -> 2697 | C25: O-2697 | D25: 46080 | E25: Aguas CAP | F25: Aguas CAP | G25: Claudia Castillo | H25: ccastilloc@aguascap.cl | I25: Proyecto Sistema de Impulsión y Transporte de Salmuera | K25: PRE | L25: LM | M25: NAC | N25: #VALUE! | O25: 46084 | P25: David Cerón | Q25: PI | R25: PIPELINES | T25: DP | V25: 46084 | Y25: =IF(SUM(W25:W25)>0,X25/SUM(W25:W25)*1000000,"N/A") -> N/A | AG25: =YEAR(V25) -> 2026 | AH25: =+IF(AG25=$AH$22,MONTH(V25),"") -> 3 | AI25: =+IF(AG25=$AI$22,MONTH(V25),"") | AJ25: =+IF(AG25=$AJ$22,MONTH(V25),"") | AK25: =+IF(AG25=$AK$22,MONTH(V25),"") | AL25: =+IF(AG25=$AL$22,MONTH(V25),"") | AM25: =+IF($AG25=$AM$22,MONTH($D25),"") | AN25: =+IF($AG25=AN$22,MONTH($D25),"") | AO25: =+IF($AG25=AO$22,MONTH($D25),"") | AP25: =+IF($AG25=AP$22,MONTH($D25),"") | AQ25: =+IF($AG25=AQ$22,MONTH($D25),"") | AR25: =+IF($AG25=AR$22,MONTH($D25),"") | AS25: =+IF($AG25=AS$22,MONTH($D25),"") | AT25: =+IF($AG25=AT$22,MONTH($D25),"") | AU25: =+IF($AG25=AU$22,MONTH($D25),"") | ... AX25: =+IF($AG25=AX$22,MONTH($D25),"")
A26: =+IFERROR(VALUE(MID(AB26,4,4)),"") | B26: =VALUE(RIGHT(C26,LEN(C26)-2)) -> 2696 | C26: O-2696 | D26: 46080 | E26: Vale | F26: Vale | G26: Erick Brito | H26: eric.brito@vale.com | I26: Reavaliação do Traçado da Tubulação de Rejeito - Mina de Fábrica | K26: RE | L26: LM | M26: INT | N26: #VALUE! | O26: 46083 | P26: Gustavo Assis | Q26: TA | R26: RELAVES | T26: DP | V26: 46087 | W26: 584 | X26: 20.246 | Y26: =IF(SUM(W26:W26)>0,X26/SUM(W26:W26)*1000000,"N/A") -> 34667.808 | AG26: =YEAR(V26) -> 2026 | AH26: =+IF(AG26=$AH$22,MONTH(V26),"") -> 3 | AI26: =+IF(AG26=$AI$22,MONTH(V26),"") | AJ26: =+IF(AG26=$AJ$22,MONTH(V26),"") | AK26: =+IF(AG26=$AK$22,MONTH(V26),"") | AL26: =+IF(AG26=$AL$22,MONTH(V26),"") | AM26: =+IF($AG26=$AM$22,MONTH($D26),"") | AN26: =+IF($AG26=AN$22,MONTH($D26),"") | AO26: =+IF($AG26=AO$22,MONTH($D26),"") | AP26: =+IF($AG26=AP$22,MONTH($D26),"") | AQ26: =+IF($AG26=AQ$22,MONTH($D26),"") | AR26: =+IF($AG26=AR$22,MONTH($D26),"") | AS26: =+IF($AG26=AS$22,MONTH($D26),"") | AT26: =+IF($AG26=AT$22,MONTH($D26),"") | AU26: =+IF($AG26=AU$22,MONTH($D26),"") | ... AX26: =+IF($AG26=AX$22,MONTH($D26),"")
A27: =+IFERROR(VALUE(MID(AB27,4,4)),"") | B27: =VALUE(RIGHT(C27,LEN(C27)-2)) -> 2695 | C27: O-2695 | D27: 46078 | E27: Vale | F27: Vale | G27: Wender Araujo | H27: c0711007@vale.com | I27: Revisão dos documentos do sistema de bombeamento das bombas do ES2058 VGR | K27: RE | L27: LC | M27: INT | N27: #VALUE! | O27: 46085 | P27: José Muñoz | Q27: PI | R27: PIPELINES | T27: DP | V27: 46085 | W27: 459 | X27: 28 | Y27: =IF(SUM(W27:W27)>0,X27/SUM(W27:W27)*1000000,"N/A") -> 61002.179 | AG27: =YEAR(V27) -> 2026 | AH27: =+IF(AG27=$AH$22,MONTH(V27),"") -> 3 | AI27: =+IF(AG27=$AI$22,MONTH(V27),"") | AJ27: =+IF(AG27=$AJ$22,MONTH(V27),"") | AK27: =+IF(AG27=$AK$22,MONTH(V27),"") | AL27: =+IF(AG27=$AL$22,MONTH(V27),"") | AM27: =+IF($AG27=$AM$22,MONTH($D27),"") | AN27: =+IF($AG27=AN$22,MONTH($D27),"") | AO27: =+IF($AG27=AO$22,MONTH($D27),"") | AP27: =+IF($AG27=AP$22,MONTH($D27),"") | AQ27: =+IF($AG27=AQ$22,MONTH($D27),"") | AR27: =+IF($AG27=AR$22,MONTH($D27),"") | AS27: =+IF($AG27=AS$22,MONTH($D27),"") | AT27: =+IF($AG27=AT$22,MONTH($D27),"") | AU27: =+IF($AG27=AU$22,MONTH($D27),"") | ... AX27: =+IF($AG27=AX$22,MONTH($D27),"")
A28: =+IFERROR(VALUE(MID(AB28,4,4)),"") | B28: =VALUE(RIGHT(C28,LEN(C28)-2)) -> 2694 | C28: O-2694 | D28: 46078 | E28: Besalco | F28: AngloAmerican | G28: Flavio Letelier | H28: flavio.letelier@besalco.cl | I28: Apoyo Ingeniería Refinoducto Definitivo Los Bronces | K28: ID | L28: LC | M28: NAC | N28: #VALUE! | O28: 46092 | P28: TBD | Q28: PI | R28: PIPELINES | T28: EP | V28: 46080 | Y28: =IF(SUM(W28:W28)>0,X28/SUM(W28:W28)*1000000,"N/A") -> N/A | AG28: =YEAR(V28) -> 2026 | AH28: =+IF(AG28=$AH$22,MONTH(V28),"") -> 2 | AI28: =+IF(AG28=$AI$22,MONTH(V28),"") | AJ28: =+IF(AG28=$AJ$22,MONTH(V28),"") | AK28: =+IF(AG28=$AK$22,MONTH(V28),"") | AL28: =+IF(AG28=$AL$22,MONTH(V28),"") | AM28: =+IF($AG28=$AM$22,MONTH($D28),"") | AN28: =+IF($AG28=AN$22,MONTH($D28),"") | AO28: =+IF($AG28=AO$22,MONTH($D28),"") | AP28: =+IF($AG28=AP$22,MONTH($D28),"") | AQ28: =+IF($AG28=AQ$22,MONTH($D28),"") | AR28: =+IF($AG28=AR$22,MONTH($D28),"") | AS28: =+IF($AG28=AS$22,MONTH($D28),"") | AT28: =+IF($AG28=AT$22,MONTH($D28),"") | AU28: =+IF($AG28=AU$22,MONTH($D28),"") | ... AX28: =+IF($AG28=AX$22,MONTH($D28),"")
A29: =+IFERROR(VALUE(MID(AB29,4,4)),"") | B29: =VALUE(RIGHT(C29,LEN(C29)-2)) -> 2693 | C29: O-2693 | D29: 46079 | E29: Vale | F29: Vale | G29: Erick Brito | H29: eric.brito@vale.com | I29: ID Projeto Detalhado para Sistema de Captação Barragem Maravilhas II Mina do Pico | K29: ID | L29: LM | M29: INT | N29: #VALUE! | O29: 46093 | P29: Gustavo Assis | Q29: TA | R29: RELAVES | T29: EP | V29: 46080 | Y29: =IF(SUM(W29:W29)>0,X29/SUM(W29:W29)*1000000,"N/A") -> N/A | AG29: =YEAR(V29) -> 2026 | AH29: =+IF(AG29=$AH$22,MONTH(V29),"") -> 2 | AI29: =+IF(AG29=$AI$22,MONTH(V29),"") | AJ29: =+IF(AG29=$AJ$22,MONTH(V29),"") | AK29: =+IF(AG29=$AK$22,MONTH(V29),"") | AL29: =+IF(AG29=$AL$22,MONTH(V29),"") | AM29: =+IF($AG29=$AM$22,MONTH($D29),"") | AN29: =+IF($AG29=AN$22,MONTH($D29),"") | AO29: =+IF($AG29=AO$22,MONTH($D29),"") | AP29: =+IF($AG29=AP$22,MONTH($D29),"") | AQ29: =+IF($AG29=AQ$22,MONTH($D29),"") | AR29: =+IF($AG29=AR$22,MONTH($D29),"") | AS29: =+IF($AG29=AS$22,MONTH($D29),"") | AT29: =+IF($AG29=AT$22,MONTH($D29),"") | AU29: =+IF($AG29=AU$22,MONTH($D29),"") | ... AX29: =+IF($AG29=AX$22,MONTH($D29),"")
A30: =+IFERROR(VALUE(MID(AB30,4,4)),"") | B30: =VALUE(RIGHT(C30,LEN(C30)-2)) -> 2692 | C30: O-2692 | D30: 46076 | E30: Vale | F30: Vale | G30: Cassio Dayrell | H30: cassio.dayrell@vale.com | I30: IB Fase 2 Otimização Circuito 0,15mm de VGR1 | K30: IB | L30: LM | M30: INT | N30: #VALUE! | O30: 46080 | P30: Gustavo Assis | Q30: TA | R30: RELAVES | T30: DP | U30: 0.1 | V30: 46080 | W30: 3386 | X30: 107 | Y30: =IF(SUM(W30:W30)>0,X30/SUM(W30:W30)*1000000,"N/A") -> 31600.709 | AG30: =YEAR(V30) -> 2026 | AH30: =+IF(AG30=$AH$22,MONTH(V30),"") -> 2 | AI30: =+IF(AG30=$AI$22,MONTH(V30),"") | AJ30: =+IF(AG30=$AJ$22,MONTH(V30),"") | AK30: =+IF(AG30=$AK$22,MONTH(V30),"") | AL30: =+IF(AG30=$AL$22,MONTH(V30),"") | AM30: =+IF($AG30=$AM$22,MONTH($D30),"") | AN30: =+IF($AG30=AN$22,MONTH($D30),"") | AO30: =+IF($AG30=AO$22,MONTH($D30),"") | AP30: =+IF($AG30=AP$22,MONTH($D30),"") | AQ30: =+IF($AG30=AQ$22,MONTH($D30),"") | AR30: =+IF($AG30=AR$22,MONTH($D30),"") | AS30: =+IF($AG30=AS$22,MONTH($D30),"") | AT30: =+IF($AG30=AT$22,MONTH($D30),"") | AU30: =+IF($AG30=AU$22,MONTH($D30),"") | ... AX30: =+IF($AG30=AX$22,MONTH($D30),"")
A31: =+IFERROR(VALUE(MID(AB31,4,4)),"") | B31: =VALUE(RIGHT(C31,LEN(C31)-2)) -> 2691 | C31: O-2691 | D31: 46073 | E31: Codelco | F31: DET | G31: ARIBA | H31: ARIBA | I31: CM Ingeniería y Estudios Multidisciplinarios GPRO - DET | K31: CM | L31: LM | M31: NAC | N31: #VALUE! | O31: 46154 | P31: David Cerón | Q31: CM | R31: CM | T31: EP | V31: 46073 | Y31: =IF(SUM(W31:W31)>0,X31/SUM(W31:W31)*1000000,"N/A") -> N/A | AG31: =YEAR(V31) -> 2026 | AH31: =+IF(AG31=$AH$22,MONTH(V31),"") -> 2 | AI31: =+IF(AG31=$AI$22,MONTH(V31),"") | AJ31: =+IF(AG31=$AJ$22,MONTH(V31),"") | AK31: =+IF(AG31=$AK$22,MONTH(V31),"") | AL31: =+IF(AG31=$AL$22,MONTH(V31),"") | AM31: =+IF($AG31=$AM$22,MONTH($D31),"") | AN31: =+IF($AG31=AN$22,MONTH($D31),"") | AO31: =+IF($AG31=AO$22,MONTH($D31),"") | AP31: =+IF($AG31=AP$22,MONTH($D31),"") | AQ31: =+IF($AG31=AQ$22,MONTH($D31),"") | AR31: =+IF($AG31=AR$22,MONTH($D31),"") | AS31: =+IF($AG31=AS$22,MONTH($D31),"") | AT31: =+IF($AG31=AT$22,MONTH($D31),"") | AU31: =+IF($AG31=AU$22,MONTH($D31),"") | ... AX31: =+IF($AG31=AX$22,MONTH($D31),"")
A32: =+IFERROR(VALUE(MID(AB32,4,4)),"") | B32: =VALUE(RIGHT(C32,LEN(C32)-2)) -> 2690 | C32: O-2690 | D32: 46072 | E32: Minera Zaldívar | F32: Minera Zaldívar | G32: Ariba | H32: ARIBA | I32: ID Losas y Topes Neumáticos Prefabricadas Chancador Primario | K32: ID | L32: LM | M32: NAC | N32: #VALUE! | O32: 46100 | P32: Luis Ilabarca | Q32: OT | R32: INFRA | T32: EP | V32: 46072 | Y32: =IF(SUM(W32:W32)>0,X32/SUM(W32:W32)*1000000,"N/A") -> N/A | AG32: =YEAR(V32) -> 2026 | AH32: =+IF(AG32=$AH$22,MONTH(V32),"") -> 2 | AI32: =+IF(AG32=$AI$22,MONTH(V32),"") | AJ32: =+IF(AG32=$AJ$22,MONTH(V32),"") | AK32: =+IF(AG32=$AK$22,MONTH(V32),"") | AL32: =+IF(AG32=$AL$22,MONTH(V32),"") | AM32: =+IF($AG32=$AM$22,MONTH($D32),"") | AN32: =+IF($AG32=AN$22,MONTH($D32),"") | AO32: =+IF($AG32=AO$22,MONTH($D32),"") | AP32: =+IF($AG32=AP$22,MONTH($D32),"") | AQ32: =+IF($AG32=AQ$22,MONTH($D32),"") | AR32: =+IF($AG32=AR$22,MONTH($D32),"") | AS32: =+IF($AG32=AS$22,MONTH($D32),"") | AT32: =+IF($AG32=AT$22,MONTH($D32),"") | AU32: =+IF($AG32=AU$22,MONTH($D32),"") | ... AX32: =+IF($AG32=AX$22,MONTH($D32),"")
A33: =+IFERROR(VALUE(MID(AB33,4,4)),"") | B33: =VALUE(RIGHT(C33,LEN(C33)-2)) -> 2689 | C33: O-2689 | D33: 46070 | E33: BHP | F33: Escondida | G33: Rita Gomes | H33: rita.gomes4@bhp.com | I33: Servicio de Gestión Integral de Proyectos Minera Escondida | K33: OS | L33: LM | M33: NAC | N33: #VALUE! | O33: 46076 | P33: - | Q33: OT | T33: NL | V33: 46076 | Y33: =IF(SUM(W33:W33)>0,X33/SUM(W33:W33)*1000000,"N/A") -> N/A | AG33: =YEAR(V33) -> 2026 | AH33: =+IF(AG33=$AH$22,MONTH(V33),"") -> 2 | AI33: =+IF(AG33=$AI$22,MONTH(V33),"") | AJ33: =+IF(AG33=$AJ$22,MONTH(V33),"") | AK33: =+IF(AG33=$AK$22,MONTH(V33),"") | AL33: =+IF(AG33=$AL$22,MONTH(V33),"") | AM33: =+IF($AG33=$AM$22,MONTH($D33),"") | AN33: =+IF($AG33=AN$22,MONTH($D33),"") | AO33: =+IF($AG33=AO$22,MONTH($D33),"") | AP33: =+IF($AG33=AP$22,MONTH($D33),"") | AQ33: =+IF($AG33=AQ$22,MONTH($D33),"") | AR33: =+IF($AG33=AR$22,MONTH($D33),"") | AS33: =+IF($AG33=AS$22,MONTH($D33),"") | AT33: =+IF($AG33=AT$22,MONTH($D33),"") | AU33: =+IF($AG33=AU$22,MONTH($D33),"") | ... AX33: =+IF($AG33=AX$22,MONTH($D33),"")
A34: =+IFERROR(VALUE(MID(AB34,4,4)),"") | B34: =VALUE(RIGHT(C34,LEN(C34)-2)) -> 2688 | C34: O-2688 | D34: 46070 | E34: Proforma | F34: Spence | G34: Dylan Vargas | H34: dvaras@proforma.cl | I34: Cursos Transporte Hidráulico de Relaves y Agua Operaciones Minera Spence | K34: CT | L34: ND | M34: NAC | N34: #VALUE! | O34: 46072 | P34: Pablo Vásquez | Q34: CO | R34: RELAVES | T34: DP | U34: 0.1 | V34: 46072 | W34: 125 | X34: 8 | Y34: =IF(SUM(W34:W34)>0,X34/SUM(W34:W34)*1000000,"N/A") -> 64000 | AG34: =YEAR(V34) -> 2026 | AH34: =+IF(AG34=$AH$22,MONTH(V34),"") -> 2 | AI34: =+IF(AG34=$AI$22,MONTH(V34),"") | AJ34: =+IF(AG34=$AJ$22,MONTH(V34),"") | AK34: =+IF(AG34=$AK$22,MONTH(V34),"") | AL34: =+IF(AG34=$AL$22,MONTH(V34),"") | AM34: =+IF($AG34=$AM$22,MONTH($D34),"") | AN34: =+IF($AG34=AN$22,MONTH($D34),"") | AO34: =+IF($AG34=AO$22,MONTH($D34),"") | AP34: =+IF($AG34=AP$22,MONTH($D34),"") | AQ34: =+IF($AG34=AQ$22,MONTH($D34),"") | AR34: =+IF($AG34=AR$22,MONTH($D34),"") | AS34: =+IF($AG34=AS$22,MONTH($D34),"") | AT34: =+IF($AG34=AT$22,MONTH($D34),"") | AU34: =+IF($AG34=AU$22,MONTH($D34),"") | ... AX34: =+IF($AG34=AX$22,MONTH($D34),"")
A35: =+IFERROR(VALUE(MID(AB35,4,4)),"") -> 271 | B35: =VALUE(RIGHT(C35,LEN(C35)-2)) -> 2687 | C35: O-2687 | D35: 46070 | E35: SGSCM | F35: SGSCM | G35: Félix Lastra | H35: Felix.Lastra@sgscm.cl | I35: Ingeniería de Detalles Implementación de Peinetas en Berma 11 | K35: ID | L35: ND | M35: NAC | N35: #VALUE! | O35: 46073 | P35: Fernando Calle | Q35: TA | R35: RELAVES | T35: PG | V35: 46076 | W35: 1355 | X35: 59 | Y35: =IF(SUM(W35:W35)>0,X35/SUM(W35:W35)*1000000,"N/A") -> 43542.435 | AB35: SH-0271 ODT-34 | AG35: =YEAR(V35) -> 2026 | AH35: =+IF(AG35=$AH$22,MONTH(V35),"") -> 2 | AI35: =+IF(AG35=$AI$22,MONTH(V35),"") | AJ35: =+IF(AG35=$AJ$22,MONTH(V35),"") | AK35: =+IF(AG35=$AK$22,MONTH(V35),"") | AL35: =+IF(AG35=$AL$22,MONTH(V35),"") | AM35: =+IF($AG35=$AM$22,MONTH($D35),"") | AN35: =+IF($AG35=AN$22,MONTH($D35),"") | AO35: =+IF($AG35=AO$22,MONTH($D35),"") | AP35: =+IF($AG35=AP$22,MONTH($D35),"") | AQ35: =+IF($AG35=AQ$22,MONTH($D35),"") | AR35: =+IF($AG35=AR$22,MONTH($D35),"") | AS35: =+IF($AG35=AS$22,MONTH($D35),"") | AT35: =+IF($AG35=AT$22,MONTH($D35),"") | AU35: =+IF($AG35=AU$22,MONTH($D35),"") | ... AX35: =+IF($AG35=AX$22,MONTH($D35),"")
A36: =+IFERROR(VALUE(MID(AB36,4,4)),"") | B36: =VALUE(RIGHT(C36,LEN(C36)-2)) -> 2686 | C36: O-2686 | D36: 46069 | E36: Codelco | F36: DET | G36: ARIBA | H36: ARIBA | I36: IB Mejoramiento Confiabilidad Sistema Eléctrico Planta Chancado Primario Colón | K36: IB | L36: LM | M36: NAC | N36: #VALUE! | O36: 46118 | P36: Vicente Salinas | Q36: OT | R36: INFRA | T36: NL | V36: 46069 | Y36: =IF(SUM(W36:W36)>0,X36/SUM(W36:W36)*1000000,"N/A") -> N/A | AG36: =YEAR(V36) -> 2026 | AH36: =+IF(AG36=$AH$22,MONTH(V36),"") -> 2 | AI36: =+IF(AG36=$AI$22,MONTH(V36),"") | AJ36: =+IF(AG36=$AJ$22,MONTH(V36),"") | AK36: =+IF(AG36=$AK$22,MONTH(V36),"") | AL36: =+IF(AG36=$AL$22,MONTH(V36),"") | AM36: =+IF($AG36=$AM$22,MONTH($D36),"") | AN36: =+IF($AG36=AN$22,MONTH($D36),"") | AO36: =+IF($AG36=AO$22,MONTH($D36),"") | AP36: =+IF($AG36=AP$22,MONTH($D36),"") | AQ36: =+IF($AG36=AQ$22,MONTH($D36),"") | AR36: =+IF($AG36=AR$22,MONTH($D36),"") | AS36: =+IF($AG36=AS$22,MONTH($D36),"") | AT36: =+IF($AG36=AT$22,MONTH($D36),"") | AU36: =+IF($AG36=AU$22,MONTH($D36),"") | ... AX36: =+IF($AG36=AX$22,MONTH($D36),"")
A37: =+IFERROR(VALUE(MID(AB37,4,4)),"") -> 352 | B37: =VALUE(RIGHT(C37,LEN(C37)-2)) -> 2685 | C37: O-2685 | D37: 46069 | E37: Codelco | F37: DMH | G37: ARIBA | H37: ARIBA | I37: Asistencia Técnica Proyectos Cierre Faenas | K37: OS | L37: LC | M37: NAC | N37: #VALUE! | O37: 46091 | P37: René Lagas | Q37: OT | R37: INFRA | T37: EP | V37: 46071 | Y37: =IF(SUM(W37:W37)>0,X37/SUM(W37:W37)*1000000,"N/A") -> N/A | AB37: SH-0352 ODS033 | AG37: =YEAR(V37) -> 2026 | AH37: =+IF(AG37=$AH$22,MONTH(V37),"") -> 2 | AI37: =+IF(AG37=$AI$22,MONTH(V37),"") | AJ37: =+IF(AG37=$AJ$22,MONTH(V37),"") | AK37: =+IF(AG37=$AK$22,MONTH(V37),"") | AL37: =+IF(AG37=$AL$22,MONTH(V37),"") | AM37: =+IF($AG37=$AM$22,MONTH($D37),"") | AN37: =+IF($AG37=AN$22,MONTH($D37),"") | AO37: =+IF($AG37=AO$22,MONTH($D37),"") | AP37: =+IF($AG37=AP$22,MONTH($D37),"") | AQ37: =+IF($AG37=AQ$22,MONTH($D37),"") | AR37: =+IF($AG37=AR$22,MONTH($D37),"") | AS37: =+IF($AG37=AS$22,MONTH($D37),"") | AT37: =+IF($AG37=AT$22,MONTH($D37),"") | AU37: =+IF($AG37=AU$22,MONTH($D37),"") | ... AX37: =+IF($AG37=AX$22,MONTH($D37),"")
A38: =+IFERROR(VALUE(MID(AB38,4,4)),"") | B38: =VALUE(RIGHT(C38,LEN(C38)-2)) -> 2684 | C38: O-2684 | D38: 46065 | E38: Vale | F38: Vale | G38: Wender Araujo | H38: arthur.pinto@vale.com | I38: IB/ID Derivação Adutora Itabirito para Cava Andaime - VGR | K38: ID | L38: LC | M38: INT | N38: #VALUE! | O38: 46087 | P38: Leandro Souza | Q38: PI | R38: PIPELINES | T38: EP | V38: 46073 | Y38: =IF(SUM(W38:W38)>0,X38/SUM(W38:W38)*1000000,"N/A") -> N/A | AG38: =YEAR(V38) -> 2026 | AH38: =+IF(AG38=$AH$22,MONTH(V38),"") -> 2 | AI38: =+IF(AG38=$AI$22,MONTH(V38),"") | AJ38: =+IF(AG38=$AJ$22,MONTH(V38),"") | AK38: =+IF(AG38=$AK$22,MONTH(V38),"") | AL38: =+IF(AG38=$AL$22,MONTH(V38),"") | AM38: =+IF($AG38=$AM$22,MONTH($D38),"") | AN38: =+IF($AG38=AN$22,MONTH($D38),"") | AO38: =+IF($AG38=AO$22,MONTH($D38),"") | AP38: =+IF($AG38=AP$22,MONTH($D38),"") | AQ38: =+IF($AG38=AQ$22,MONTH($D38),"") | AR38: =+IF($AG38=AR$22,MONTH($D38),"") | AS38: =+IF($AG38=AS$22,MONTH($D38),"") | AT38: =+IF($AG38=AT$22,MONTH($D38),"") | AU38: =+IF($AG38=AU$22,MONTH($D38),"") | ... AX38: =+IF($AG38=AX$22,MONTH($D38),"")
A39: =+IFERROR(VALUE(MID(AB39,4,4)),"") | B39: =VALUE(RIGHT(C39,LEN(C39)-2)) -> 2683 | C39: O-2683 | D39: 46065 | E39: Aguas CAP | F39: Aguas CAP | G39: Gabriela Pardo | H39: gpardo@aguascap.cl | I39: Ingeniería Implementación Planta de Filtrado | K39: ID | L39: LC | M39: NAC | N39: #VALUE! | O39: 46079 | P39: Carolina Bohn | Q39: PI | R39: PIPELINES | T39: DP | U39: 0.1 | V39: 46065 | W39: 4274 | X39: 197 | Y39: =IF(SUM(W39:W39)>0,X39/SUM(W39:W39)*1000000,"N/A") -> 46092.653 | AG39: =YEAR(V39) -> 2026 | AH39: =+IF(AG39=$AH$22,MONTH(V39),"") -> 2 | AI39: =+IF(AG39=$AI$22,MONTH(V39),"") | AJ39: =+IF(AG39=$AJ$22,MONTH(V39),"") | AK39: =+IF(AG39=$AK$22,MONTH(V39),"") | AL39: =+IF(AG39=$AL$22,MONTH(V39),"") | AM39: =+IF($AG39=$AM$22,MONTH($D39),"") | AN39: =+IF($AG39=AN$22,MONTH($D39),"") | AO39: =+IF($AG39=AO$22,MONTH($D39),"") | AP39: =+IF($AG39=AP$22,MONTH($D39),"") | AQ39: =+IF($AG39=AQ$22,MONTH($D39),"") | AR39: =+IF($AG39=AR$22,MONTH($D39),"") | AS39: =+IF($AG39=AS$22,MONTH($D39),"") | AT39: =+IF($AG39=AT$22,MONTH($D39),"") | AU39: =+IF($AG39=AU$22,MONTH($D39),"") | ... AX39: =+IF($AG39=AX$22,MONTH($D39),"")
A40: =+IFERROR(VALUE(MID(AB40,4,4)),"") | B40: =VALUE(RIGHT(C40,LEN(C40)-2)) -> 2682 | C40: O-2682 | D40: 46065 | E40: Centinela | F40: Centinela | G40: Constanza Alcayaga | H40: calcayaga.oti@mineracentinela.cl | I40: Cursos de Aguas y Relaves | K40: CT | L40: ND | M40: NAC | N40: #VALUE! | O40: 46078 | P40: José Muñoz | Q40: CO | R40: RELAVES | T40: DP | U40: 0.1 | V40: 46065 | W40: 228 | X40: 16 | Y40: =IF(SUM(W40:W40)>0,X40/SUM(W40:W40)*1000000,"N/A") -> 70175.439 | AG40: =YEAR(V40) -> 2026 | AH40: =+IF(AG40=$AH$22,MONTH(V40),"") -> 2 | AI40: =+IF(AG40=$AI$22,MONTH(V40),"") | AJ40: =+IF(AG40=$AJ$22,MONTH(V40),"") | AK40: =+IF(AG40=$AK$22,MONTH(V40),"") | AL40: =+IF(AG40=$AL$22,MONTH(V40),"") | AM40: =+IF($AG40=$AM$22,MONTH($D40),"") | AN40: =+IF($AG40=AN$22,MONTH($D40),"") | AO40: =+IF($AG40=AO$22,MONTH($D40),"") | AP40: =+IF($AG40=AP$22,MONTH($D40),"") | AQ40: =+IF($AG40=AQ$22,MONTH($D40),"") | AR40: =+IF($AG40=AR$22,MONTH($D40),"") | AS40: =+IF($AG40=AS$22,MONTH($D40),"") | AT40: =+IF($AG40=AT$22,MONTH($D40),"") | AU40: =+IF($AG40=AU$22,MONTH($D40),"") | ... AX40: =+IF($AG40=AX$22,MONTH($D40),"")
A41: =+IFERROR(VALUE(MID(AB41,4,4)),"") | B41: =VALUE(RIGHT(C41,LEN(C41)-2)) -> 2681 | C41: O-2681 | D41: 46064 | E41: IMECPRO | F41: Oxiquim | G41: Pablo Matus | H41: pablo.matus@imecpro.cl | I41: Diseño Ingeniería Tacos en Productivo | K41: IB | L41: ND | M41: NAC | N41: #VALUE! | O41: 46072 | P41: Luis Ilabarca | Q41: IN | R41: I+D | T41: DP | U41: 0.1 | V41: 46072 | W41: 1033 | X41: 52 | Y41: =IF(SUM(W41:W41)>0,X41/SUM(W41:W41)*1000000,"N/A") -> 50338.819 | AG41: =YEAR(V41) -> 2026 | AH41: =+IF(AG41=$AH$22,MONTH(V41),"") -> 2 | AI41: =+IF(AG41=$AI$22,MONTH(V41),"") | AJ41: =+IF(AG41=$AJ$22,MONTH(V41),"") | AK41: =+IF(AG41=$AK$22,MONTH(V41),"") | AL41: =+IF(AG41=$AL$22,MONTH(V41),"") | AM41: =+IF($AG41=$AM$22,MONTH($D41),"") | AN41: =+IF($AG41=AN$22,MONTH($D41),"") | AO41: =+IF($AG41=AO$22,MONTH($D41),"") | AP41: =+IF($AG41=AP$22,MONTH($D41),"") | AQ41: =+IF($AG41=AQ$22,MONTH($D41),"") | AR41: =+IF($AG41=AR$22,MONTH($D41),"") | AS41: =+IF($AG41=AS$22,MONTH($D41),"") | AT41: =+IF($AG41=AT$22,MONTH($D41),"") | AU41: =+IF($AG41=AU$22,MONTH($D41),"") | ... AX41: =+IF($AG41=AX$22,MONTH($D41),"")
A42: =+IFERROR(VALUE(MID(AB42,4,4)),"") | B42: =VALUE(RIGHT(C42,LEN(C42)-2)) -> 2680 | C42: O-2680 | D42: 46065 | E42: Codelco | F42: DAND | G42: ARIBA | H42: ARIBA | I42: IF Mejoramiento Condiciones Ambientales Sistema de Chancado | K42: IF | L42: LM | M42: NAC | N42: #VALUE! | O42: 46107 | P42: TBD | Q42: BP | R42: INFRA | T42: NL | V42: 46064 | Y42: =IF(SUM(W42:W42)>0,X42/SUM(W42:W42)*1000000,"N/A") -> N/A | AG42: =YEAR(V42) -> 2026 | AH42: =+IF(AG42=$AH$22,MONTH(V42),"") -> 2 | AI42: =+IF(AG42=$AI$22,MONTH(V42),"") | AJ42: =+IF(AG42=$AJ$22,MONTH(V42),"") | AK42: =+IF(AG42=$AK$22,MONTH(V42),"") | AL42: =+IF(AG42=$AL$22,MONTH(V42),"") | AM42: =+IF($AG42=$AM$22,MONTH($D42),"") | AN42: =+IF($AG42=AN$22,MONTH($D42),"") | AO42: =+IF($AG42=AO$22,MONTH($D42),"") | AP42: =+IF($AG42=AP$22,MONTH($D42),"") | AQ42: =+IF($AG42=AQ$22,MONTH($D42),"") | AR42: =+IF($AG42=AR$22,MONTH($D42),"") | AS42: =+IF($AG42=AS$22,MONTH($D42),"") | AT42: =+IF($AG42=AT$22,MONTH($D42),"") | AU42: =+IF($AG42=AU$22,MONTH($D42),"") | ... AX42: =+IF($AG42=AX$22,MONTH($D42),"")
...

Sheet Sheet1
A1: Razones de no adjudicación
A2: Costo
A3: Alcance
A4: Metodología
A5: Trabajo previo ejecutado por competidor adjudicado
A6: Otras

Sheet Hoja1
A22: Modulo | B22: Letra | C22: Descripcion | D22: Años de Experiencia
A23: Módulo A | B23: A | C23: Ingeniería estructural
A24: Módulo B | B24: B | C24: Ingeniería de Mantenimiento y Confiabilidad | D24: > = 8 Años
A25: Módulo C | B25: C | C25: Hidráulica, manejo de pulpas y Análisis CFD | D25: > = 5 Años
A26: Módulo D | B26: D | C26: Mecánica aplicada y Análisis FEA | D26: > = 5 Años
A27: Módulo E | B27: E | C27: Diseño de sistemas de transporte y manejo de sólidos a granel y análisis DEM | D27: > = 5 Años
A28: Módulo F | B28: F | C28: Diseño de máquinas y soluciones de Mantenibilidad | D28: > = 8 Años
A29: Módulo G | B29: G | C29: Electricidad e Instrumentación | D29: > = 5 Años
A30: Módulo H | B30: H | C30: Reingeniería | D30: > = 5 Años

Sheet Hoja3
L1: T. Promedio
C2: 1883 | E2: 47.2484 | F2: 25092.087 | G2: SH-0158 OS14 | H2: 2018 | I2: =IFERROR(F2*(C2/SUMIF(H:H,H2,C:C)),0) -> 25092.087 | K2: 2010 | L2: =SUMIF(H:H,K2,I:I) -> 42212.266
C3: 441 | E3: 11.172 | F3: 25333.333 | G3: SH-0158 OS13 | H3: 2017 | I3: =IFERROR(F3*(C3/SUMIF(H:H,H3,C:C)),0) -> 280.06317 | K3: 2011 | L3: =SUMIF(H:H,K3,I:I) -> 29980.385 | M3: =(L3-L2)/L2 -> -0.28977079
C4: 1315 | E4: 32.3871 | F4: 24628.973 | G4: SH-0158 OS12 | H4: 2017 | I4: =IFERROR(F4*(C4/SUMIF(H:H,H4,C:C)),0) -> 811.8899 | K4: 2012 | L4: =SUMIF(H:H,K4,I:I) -> 32701.369 | M4: =(L4-L3)/L3 -> 0.090758829
C5: 37 | E5: 1.4418 | F5: 38967.568 | G5: SH-0158 OS11 | H5: 2017 | I5: =IFERROR(F5*(C5/SUMIF(H:H,H5,C:C)),0) -> 36.143491 | K5: 2013 | L5: =SUMIF(H:H,K5,I:I) -> 34915.704 | M5: =(L5-L4)/L4 -> 0.067713831
C6: 1065 | E6: 34.591489 | F6: 32480.271 | H6: 2017 | I6: =IFERROR(F6*(C6/SUMIF(H:H,H6,C:C)),0) -> 867.15021 | K6: 2014 | L6: =SUMIF(H:H,K6,I:I) -> 39753.104 | M6: =(L6-L5)/L5 -> 0.13854509
C7: 1144 | E7: 29.4768 | F7: 25766.434 | G7: SH-0158 OS10 | H7: 2017 | I7: =IFERROR(F7*(C7/SUMIF(H:H,H7,C:C)),0) -> 738.93359 | K7: 2015 | L7: =SUMIF(H:H,K7,I:I) -> 33822.964 | M7: =(L7-L6)/L6 -> -0.14917426
C8: 109 | E8: 2.560908 | F8: 23494.569 | G8: SH-0173 | H8: 2017 | I8: =IFERROR(F8*(C8/SUMIF(H:H,H8,C:C)),0) -> 64.197639 | K8: 2016 | L8: =SUMIF(H:H,K8,I:I) -> 31922.001 | M8: =(L8-L7)/L7 -> -0.056203316
C9: 800 | E9: 26.124748 | F9: 32655.935 | G9: SH-0174 | H9: 2017 | I9: =IFERROR(F9*(C9/SUMIF(H:H,H9,C:C)),0) -> 654.90331 | K9: 2017 | L9: =SUMIF(H:H,K9,I:I) -> 26889.388 | M9: =(L9-L8)/L8 -> -0.15765343 | N9: =(L9-L7)/L7 -> -0.2049961
C10: 240 | E10: 8.0864 | F10: 33693.333 | G10: SH0158-OS09 | H10: 2017 | I10: =IFERROR(F10*(C10/SUMIF(H:H,H10,C:C)),0) -> 202.71239 | K10: 2018 | L10: =SUMIF(H:H,K10,I:I) -> 25092.087 | M10: =(L10-L9)/L9 -> -0.066840534
C11: 80 | E11: 2.926 | F11: 36575 | G11: SH0171 | H11: 2017 | I11: =IFERROR(F11*(C11/SUMIF(H:H,H11,C:C)),0) -> 73.349878
C12: 232 | E12: 7.5012 | F12: 32332.759 | G12: SH0170 | H12: 2017 | I12: =IFERROR(F12*(C12/SUMIF(H:H,H12,C:C)),0) -> 188.04242
C13: 30 | E13: 0.7238 | F13: 24126.667 | H13: 2017 | I13: =IFERROR(F13*(C13/SUMIF(H:H,H13,C:C)),0) -> 18.144444
C14: 525 | E14: 12.635 | F14: 24066.667 | G14: SH0158-OS08 | H14: 2017 | I14: =IFERROR(F14*(C14/SUMIF(H:H,H14,C:C)),0) -> 316.73811
C15: 1240 | E15: 27.664 | F15: 22309.677 | G15: SH0158-OS07 | H15: 2017 | I15: =IFERROR(F15*(C15/SUMIF(H:H,H15,C:C)),0) -> 693.48976
C16: 942 | E16: 25.024125 | F16: 26564.889 | G16: SH0158-OS06 | H16: 2017 | I16: =IFERROR(F16*(C16/SUMIF(H:H,H16,C:C)),0) -> 627.31256
C17: 175 | E17: 3.818261 | F17: 21818.634 | G17: SH0169 | H17: 2017 | I17: =IFERROR(F17*(C17/SUMIF(H:H,H17,C:C)),0) -> 95.717355
C18: 2135 | E18: 59.995262 | F18: 28100.825 | G18: SH0172 | H18: 2017 | I18: =IFERROR(F18*(C18/SUMIF(H:H,H18,C:C)),0) -> 1503.9799
C19: 396 | E19: 10.66372 | F19: 26928.586 | G19: SH0158-OS05 | H19: 2017 | I19: =IFERROR(F19*(C19/SUMIF(H:H,H19,C:C)),0) -> 267.32145
C20: 1058 | E20: 27.8768 | F20: 26348.582 | G20: SH0158-OS04 | H20: 2017 | I20: =IFERROR(F20*(C20/SUMIF(H:H,H20,C:C)),0) -> 698.8243
C21: 37 | E21: 1.4364 | F21: 38821.622 | G21: SH-0158 OS02 | H21: 2017 | I21: =IFERROR(F21*(C21/SUMIF(H:H,H21,C:C)),0) -> 36.008122
C22: 100 | E22: 2.66 | F22: 26600 | G22: SH-0164 | H22: 2017 | I22: =IFERROR(F22*(C22/SUMIF(H:H,H22,C:C)),0) -> 66.681708
C23: 192 | E23: 3.4216245 | F23: 17820.961 | G23: SH-0157 | H23: 2017 | I23: =IFERROR(F23*(C23/SUMIF(H:H,H23,C:C)),0) -> 85.774348
G24: SH-0159 | H24: 2017 | I24: =IFERROR(F24*(C24/SUMIF(H:H,H24,C:C)),0) -> 0
C25: 200 | G25: SH-0165 | H25: 2017 | I25: =IFERROR(F25*(C25/SUMIF(H:H,H25,C:C)),0) -> 0
C26: 20 | E26: 1.24285 | F26: 62142.5 | G26: SH-0160 | H26: 2017 | I26: =IFERROR(F26*(C26/SUMIF(H:H,H26,C:C)),0) -> 31.156151
C27: 142 | E27: 3.8159357 | F27: 26872.787 | G27: SH-0158 OS03 | H27: 2017 | I27: =IFERROR(F27*(C27/SUMIF(H:H,H27,C:C)),0) -> 95.659063
C28: 739 | E28: 29.736774 | F28: 40239.207 | G28: SH-0162 | H28: 2017 | I28: =IFERROR(F28*(C28/SUMIF(H:H,H28,C:C)),0) -> 745.4507
C29: 3159 | E29: 121.70334 | F29: 38525.907 | G29: SH-0166 | H29: 2017 | I29: =IFERROR(F29*(C29/SUMIF(H:H,H29,C:C)),0) -> 3050.8972
C30: 4000 | E30: 39.08722 | F30: 9771.805 | G30: SH-0146 | H30: 2017 | I30: =IFERROR(F30*(C30/SUMIF(H:H,H30,C:C)),0) -> 979.85059
C31: 445 | E31: 11.827655 | F31: 26579 | H31: 2017 | I31: =IFERROR(F31*(C31/SUMIF(H:H,H31,C:C)),0) -> 296.49934
C32: 210 | E32: 7.40259 | F32: 35250.429 | G32: SH-0156 | H32: 2017 | I32: =IFERROR(F32*(C32/SUMIF(H:H,H32,C:C)),0) -> 185.57043
C33: 397 | E33: 5.245035 | F33: 13211.675 | G33: SH-0151 | H33: 2017 | I33: =IFERROR(F33*(C33/SUMIF(H:H,H33,C:C)),0) -> 131.48417
G34: SH-0168 | H34: 2017 | I34: =IFERROR(F34*(C34/SUMIF(H:H,H34,C:C)),0) -> 0
C35: 468 | E35: 11.52348 | F35: 24622.821 | G35: SH-0163 | H35: 2017 | I35: =IFERROR(F35*(C35/SUMIF(H:H,H35,C:C)),0) -> 288.87418
C36: 810 | E36: 24.13059 | F36: 29790.852 | H36: 2017 | I36: =IFERROR(F36*(C36/SUMIF(H:H,H36,C:C)),0) -> 604.91314
C37: 524 | E37: 19.0224 | F37: 36302.29 | G37: SH-0154 | H37: 2017 | I37: =IFERROR(F37*(C37/SUMIF(H:H,H37,C:C)),0) -> 476.85944
C38: 2922 | E38: 82.052222 | F38: 28080.843 | G38: SH-0161 | H38: 2017 | I38: =IFERROR(F38*(C38/SUMIF(H:H,H38,C:C)),0) -> 2056.9106
C39: 621 | E39: 20.019808 | F39: 32238.016 | G39: SH-0153 | H39: 2017 | I39: =IFERROR(F39*(C39/SUMIF(H:H,H39,C:C)),0) -> 501.86278
C40: 2291 | E40: 69.21882 | F40: 30213.365 | G40: SH-0155 | H40: 2017 | I40: =IFERROR(F40*(C40/SUMIF(H:H,H40,C:C)),0) -> 1735.1989
...

Sheet Indicadores
AU2: HH EJECUTADAS | BN2: =SUMIFS(Ofertas!W2374:W2765,Ofertas!T2374:T2765,Indicadores!A6,Ofertas!AG2374:AG2765,Indicadores!B3) -> 8661 | BP2: AÑOS | BQ2: TIPO DE NEGOCIACIÓN
B3: 2010 | K3: 2010 | L3: ND | M3: NEGOCIACIÓN DIRECTA | T3: 2010 | U3: LM | V3: LICITACIÓN MÚLTIPLE | AU3: AÑO | AV3: HH REALES | BP3: 2010 | BQ3: ND | BR3: ND: Negociación Directa
B4: STATUS (a la fecha) | C4: Can. | D4: % | E4: hh Lic. | F4: % hh | G4: M$ Lic. | H4: % M$ | K4: STATUS (a la fecha) | L4: Can. | M4: % | N4: hh Lic. | O4: % hh | P4: M$ Lic. | Q4: % M$ | T4: STATUS (a la fecha) | U4: Can. | V4: % | W4: hh Lic. | X4: % hh | Y4: M$ Lic. | Z4: % M$ | AU4: 2010 | AV4: 6000 | BP4: 2011 | BQ4: LM | BR4: LM: Licitación Multiple
B5: Totales | C5: =SUM(C6:C10) -> 51 | D5: =SUM(D6:D10) -> 59.235294 | E5: =SUM(E6:E10) -> 58189 | F5: =SUM(F6:F10) -> 1 | G5: =SUM(G6:G10) -> 1776.7818 | H5: =SUM(H6:H10) -> 100 | K5: Totales | L5: =SUM(L6:L10) -> 45 | M5: =SUM(M6:M10) -> 100 | N5: =SUM(N6:N10) -> 32472 | O5: =SUM(O6:O10) -> 73.594512 | P5: =SUM(P6:P10) -> 1022.4408 | Q5: =SUM(Q6:Q10) -> 100 | T5: Totales | U5: =SUM(U6:U10) -> 6 | V5: =SUM(V6:V10) -> 100 | W5: =SUM(W6:W10) -> 25717 | X5: =SUM(X6:X10) -> 100 | Y5: =SUM(Y6:Y10) -> 754.341 | Z5: =SUM(Z6:Z10) -> 100 | AU5: 2011 | AV5: 25871.607 | BP5: 2012 | BQ5: AC | BR5: AC: Apoyo Contratos
A6: PG | B6: Propuestas Ganadas | C6: =COUNTIFS(Ofertas!$T$2242:$T$2765,Indicadores!A6,Ofertas!$AG$2242:$AG$2765,$B$3) -> 21 | D6: =C6/$C$5 -> 0.41176471 | E6: =SUMIFS(Ofertas!$W$2242:$W$2765,Ofertas!$T$2242:$T$2765,Indicadores!A6,Ofertas!$AG$2242:$AG$2765,Indicadores!$B$3) -> 8661 | F6: =E6/$E$5 -> 0.14884256 | G6: =SUMIFS(Ofertas!$X$2242:$X$2765,Ofertas!$T$2242:$T$2765,Indicadores!A6,Ofertas!$AG$2242:$AG$2765,Indicadores!$B$3) -> 365.60044 | H6: =G6/$G$5*100 -> 20.576553 | J6: PG | K6: Propuestas Ganadas | L6: =COUNTIFS(Ofertas!$T$2242:$T$2765,Indicadores!J6,Ofertas!$AG$2242:$AG$2765,$K$3,Ofertas!$L$2242:$L$2765,Indicadores!$L$3) -> 21 | M6: =L6/$L$5*100 -> 46.666667 | N6: =SUMIFS(Ofertas!$W$2242:$W$2765,Ofertas!$T$2242:$T$2765,Indicadores!J6,Ofertas!$AG$2242:$AG$2765,Indicadores!$K$3,Ofertas!$L$2242:$L$2765,Indicadores!$L$3) -> 8661 | O6: =N6/$N$5 -> 0.2667221 | P6: =SUMIFS(Ofertas!$X$2242:$X$2765,Ofertas!$T$2242:$T$2765,Indicadores!J6,Ofertas!$AG$2242:$AG$2765,Indicadores!$K$3,Ofertas!$L$2242:$L$2765,Indicadores!$L$3) -> 365.60044 | Q6: =P6/$P$5*100 -> 35.757616 | S6: PG | T6: Propuestas Ganadas | U6: =COUNTIFS(Ofertas!$T$2242:$T$2765,Indicadores!S6,Ofertas!$AG$2242:$AG$2765,$T$3,Ofertas!$L$2242:$L$2765,Indicadores!$U$3) -> 0 | V6: =U6/$U$5*100 -> 0 | W6: =SUMIFS(Ofertas!$W$2242:$W$2765,Ofertas!$T$2242:$T$2765,Indicadores!S6,Ofertas!$AG$2242:$AG$2765,Indicadores!$T$3,Ofertas!$L$2242:$L$2765,Indicadores!$U$3) -> 0 | X6: =W6/$W$5 -> 0 | Y6: =SUMIFS(Ofertas!$X$2242:$X$2765,Ofertas!$T$2242:$T$2765,Indicadores!S6,Ofertas!$AG$2242:$AG$2765,Indicadores!$T$3,Ofertas!$L$2242:$L$2765,Indicadores!$U$3) -> 0 | Z6: =Y6/$Y$5*100 -> 0 | AU6: 2012 | AV6: 25836.367 | BP6: 2013 | BQ6: LC | BR6: LC: Licitación Contrato Abierto
A7: PP | B7: Propuestas Perdidas | C7: =COUNTIFS(Ofertas!$T$2242:$T$2765,Indicadores!A7,Ofertas!$AG$2242:$AG$2765,$B$3) -> 30 | D7: =C7/$C$5*100 -> 58.823529 | E7: =SUMIFS(Ofertas!$W$2242:$W$2765,Ofertas!$T$2242:$T$2765,Indicadores!A7,Ofertas!$AG$2242:$AG$2765,Indicadores!$B$3) -> 49528 | F7: =E7/$E$5 -> 0.85115744 | G7: =SUMIFS(Ofertas!$X$2242:$X$2765,Ofertas!$T$2242:$T$2765,Indicadores!A7,Ofertas!$AG$2242:$AG$2765,Indicadores!$B$3) -> 1411.1813 | H7: =G7/$G$5*100 -> 79.423447 | J7: PP | K7: Propuestas Perdidas | L7: =COUNTIFS(Ofertas!$T$2242:$T$2765,Indicadores!J7,Ofertas!$AG$2242:$AG$2765,$K$3,Ofertas!$L$2242:$L$2765,Indicadores!$L$3) -> 24 | M7: =L7/$L$5*100 -> 53.333333 | N7: =SUMIFS(Ofertas!$W$2242:$W$2765,Ofertas!$T$2242:$T$2765,Indicadores!J7,Ofertas!$AG$2242:$AG$2765,Indicadores!$K$3,Ofertas!$L$2242:$L$2765,Indicadores!$L$3) -> 23811 | O7: =N7/$N$5*100 -> 73.32779 | P7: =SUMIFS(Ofertas!$X$2242:$X$2765,Ofertas!$T$2242:$T$2765,Indicadores!J7,Ofertas!$AG$2242:$AG$2765,Indicadores!$K$3,Ofertas!$L$2242:$L$2765,Indicadores!$L$3) -> 656.84032 | Q7: =P7/$P$5*100 -> 64.242384 | S7: PP | T7: Propuestas Perdidas | U7: =COUNTIFS(Ofertas!$T$2242:$T$2765,Indicadores!S7,Ofertas!$AG$2242:$AG$2765,$T$3,Ofertas!$L$2242:$L$2765,Indicadores!$U$3) -> 6 | V7: =U7/$U$5*100 -> 100 | W7: =SUMIFS(Ofertas!$W$2242:$W$2765,Ofertas!$T$2242:$T$2765,Indicadores!S7,Ofertas!$AG$2242:$AG$2765,Indicadores!$T$3,Ofertas!$L$2242:$L$2765,Indicadores!$U$3) -> 25717 | X7: =W7/$W$5*100 -> 100 | Y7: =SUMIFS(Ofertas!$X$2242:$X$2765,Ofertas!$T$2242:$T$2765,Indicadores!S7,Ofertas!$AG$2242:$AG$2765,Indicadores!$T$3,Ofertas!$L$2242:$L$2765,Indicadores!$U$3) -> 754.341 | Z7: =Y7/$Y$5*100 -> 100 | AU7: 2013 | AV7: 23559 | BP7: 2014 | BQ7: N/A | BR7: N/A: No Aplica
A8: PD | B8: Propuestas Desiertas | C8: =COUNTIFS(Ofertas!$T$2242:$T$2765,Indicadores!A8,Ofertas!$AG$2242:$AG$2765,$B$3) -> 0 | D8: =C8/$C$5*100 -> 0 | E8: =SUMIFS(Ofertas!$W$2242:$W$2765,Ofertas!$T$2242:$T$2765,Indicadores!A8,Ofertas!$AG$2242:$AG$2765,Indicadores!$B$3) -> 0 | F8: =E8/$E$5*100 -> 0 | G8: =SUMIFS(Ofertas!$X$2242:$X$2765,Ofertas!$T$2242:$T$2765,Indicadores!A8,Ofertas!$AG$2242:$AG$2765,Indicadores!$B$3) -> 0 | H8: =G8/$G$5*100 -> 0 | J8: PD | K8: Propuestas Desiertas | L8: =COUNTIFS(Ofertas!$T$2242:$T$2765,Indicadores!J8,Ofertas!$AG$2242:$AG$2765,$K$3,Ofertas!$L$2242:$L$2765,Indicadores!$L$3) -> 0 | M8: =L8/$L$5*100 -> 0 | N8: =SUMIFS(Ofertas!$W$2242:$W$2765,Ofertas!$T$2242:$T$2765,Indicadores!J8,Ofertas!$AG$2242:$AG$2765,Indicadores!$K$3,Ofertas!$L$2242:$L$2765,Indicadores!$L$3) -> 0 | O8: =N8/$N$5*100 -> 0 | P8: =SUMIFS(Ofertas!$X$2242:$X$2765,Ofertas!$T$2242:$T$2765,Indicadores!J8,Ofertas!$AG$2242:$AG$2765,Indicadores!$K$3,Ofertas!$L$2242:$L$2765,Indicadores!$L$3) -> 0 | Q8: =P8/$P$5*100 -> 0 | S8: PD | T8: Propuestas Desiertas | U8: =COUNTIFS(Ofertas!$T$2242:$T$2765,Indicadores!S8,Ofertas!$AG$2242:$AG$2765,$T$3,Ofertas!$L$2242:$L$2765,Indicadores!$U$3) -> 0 | V8: =U8/$U$5*100 -> 0 | W8: =SUMIFS(Ofertas!$W$2242:$W$2765,Ofertas!$T$2242:$T$2765,Indicadores!S8,Ofertas!$AG$2242:$AG$2765,Indicadores!$T$3,Ofertas!$L$2242:$L$2765,Indicadores!$U$3) -> 0 | X8: =W8/$W$5*100 -> 0 | Y8: =SUMIFS(Ofertas!$X$2242:$X$2765,Ofertas!$T$2242:$T$2765,Indicadores!S8,Ofertas!$AG$2242:$AG$2765,Indicadores!$T$3,Ofertas!$L$2242:$L$2765,Indicadores!$U$3) -> 0 | Z8: =Y8/$Y$5*100 -> 0 | AU8: 2014 | AV8: 33299 | BP8: 2015
A9: DP | B9: Decisión del Cliente Pendiente | C9: =COUNTIFS(Ofertas!$T$2242:$T$2765,Indicadores!A9,Ofertas!$AG$2242:$AG$2765,$B$3) -> 0 | D9: =C9/$C$5*100 -> 0 | E9: =SUMIFS(Ofertas!$W$2242:$W$2765,Ofertas!$T$2242:$T$2765,Indicadores!A9,Ofertas!$AG$2242:$AG$2765,Indicadores!$B$3) -> 0 | F9: =E9/$E$5*100 -> 0 | G9: =SUMIFS(Ofertas!$X$2242:$X$2765,Ofertas!$T$2242:$T$2765,Indicadores!A9,Ofertas!$AG$2242:$AG$2765,Indicadores!$B$3) -> 0 | H9: =G9/$G$5*100 -> 0 | J9: DP | K9: Decisión del Cliente Pendiente | L9: =COUNTIFS(Ofertas!$T$2242:$T$2765,Indicadores!J9,Ofertas!$AG$2242:$AG$2765,$K$3,Ofertas!$L$2242:$L$2765,Indicadores!$L$3) -> 0 | M9: =L9/$L$5*100 -> 0 | N9: =SUMIFS(Ofertas!$W$2242:$W$2765,Ofertas!$T$2242:$T$2765,Indicadores!J9,Ofertas!$AG$2242:$AG$2765,Indicadores!$K$3,Ofertas!$L$2242:$L$2765,Indicadores!$L$3) -> 0 | O9: =N9/$N$5*100 -> 0 | P9: =SUMIFS(Ofertas!$X$2242:$X$2765,Ofertas!$T$2242:$T$2765,Indicadores!J9,Ofertas!$AG$2242:$AG$2765,Indicadores!$K$3,Ofertas!$L$2242:$L$2765,Indicadores!$L$3) -> 0 | Q9: =P9/$P$5*100 -> 0 | S9: DP | T9: Decisión del Cliente Pendiente | U9: =COUNTIFS(Ofertas!$T$2242:$T$2765,Indicadores!S9,Ofertas!$AG$2242:$AG$2765,$T$3,Ofertas!$L$2242:$L$2765,Indicadores!$U$3) -> 0 | V9: =U9/$U$5*100 -> 0 | W9: =SUMIFS(Ofertas!$W$2242:$W$2765,Ofertas!$T$2242:$T$2765,Indicadores!S9,Ofertas!$AG$2242:$AG$2765,Indicadores!$T$3,Ofertas!$L$2242:$L$2765,Indicadores!$U$3) -> 0 | X9: =W9/$W$5*100 -> 0 | Y9: =SUMIFS(Ofertas!$X$2242:$X$2765,Ofertas!$T$2242:$T$2765,Indicadores!S9,Ofertas!$AG$2242:$AG$2765,Indicadores!$T$3,Ofertas!$L$2242:$L$2765,Indicadores!$U$3) -> 0 | Z9: =Y9/$Y$5*100 -> 0 | AU9: 2015 | AV9: 49033 | BP9: 2016
A10: EP | B10: Propuestas en Preparación | C10: =COUNTIFS(Ofertas!$T$2242:$T$2765,Indicadores!A10,Ofertas!$AG$2242:$AG$2765,$B$3) -> 0 | D10: =C10/$C$5*100 -> 0 | E10: =SUMIFS(Ofertas!$W$2242:$W$2765,Ofertas!$T$2242:$T$2765,Indicadores!A10,Ofertas!$AG$2242:$AG$2765,Indicadores!$B$3) -> 0 | F10: =E10/$E$5*100 -> 0 | G10: =SUMIFS(Ofertas!$X$2242:$X$2765,Ofertas!$T$2242:$T$2765,Indicadores!A10,Ofertas!$AG$2242:$AG$2765,Indicadores!$B$3) -> 0 | H10: =G10/$G$5*100 -> 0 | J10: EP | K10: Propuestas en Preparación | L10: =COUNTIFS(Ofertas!$T$2242:$T$2765,Indicadores!J10,Ofertas!$AG$2242:$AG$2765,$K$3,Ofertas!$L$2242:$L$2765,Indicadores!$L$3) -> 0 | M10: =L10/$L$5*100 -> 0 | N10: =SUMIFS(Ofertas!$W$2242:$W$2765,Ofertas!$T$2242:$T$2765,Indicadores!J10,Ofertas!$AG$2242:$AG$2765,Indicadores!$K$3,Ofertas!$L$2242:$L$2765,Indicadores!$L$3) -> 0 | O10: =N10/$N$5*100 -> 0 | P10: =SUMIFS(Ofertas!$X$2242:$X$2765,Ofertas!$T$2242:$T$2765,Indicadores!J10,Ofertas!$AG$2242:$AG$2765,Indicadores!$K$3,Ofertas!$L$2242:$L$2765,Indicadores!$L$3) -> 0 | Q10: =P10/$P$5*100 -> 0 | S10: EP | T10: Propuestas en Preparación | U10: =COUNTIFS(Ofertas!$T$2242:$T$2765,Indicadores!S10,Ofertas!$AG$2242:$AG$2765,$T$3,Ofertas!$L$2242:$L$2765,Indicadores!$U$3) -> 0 | V10: =U10/$U$5*100 -> 0 | W10: =SUMIFS(Ofertas!$W$2242:$W$2765,Ofertas!$T$2242:$T$2765,Indicadores!S10,Ofertas!$AG$2242:$AG$2765,Indicadores!$T$3,Ofertas!$L$2242:$L$2765,Indicadores!$U$3) -> 0 | X10: =W10/$W$5*100 -> 0 | Y10: =SUMIFS(Ofertas!$X$2242:$X$2765,Ofertas!$T$2242:$T$2765,Indicadores!S10,Ofertas!$AG$2242:$AG$2765,Indicadores!$T$3,Ofertas!$L$2242:$L$2765,Indicadores!$U$3) -> 0 | Z10: =Y10/$Y$5*100 -> 0 | AU10: 2016 | AV10: 76874.895
AU11: 2017 | AV11: 60269
B12: 2011 | K12: 2011 | L12: ND | M12: NEGOCIACIÓN DIRECTA | T12: 2011 | U12: LM | V12: LICITACIÓN MÚLTIPLE | AU12: 2018 | AV12: 42085
B13: STATUS (a la fecha) | C13: Can. | D13: % | E13: hh Lic. | F13: % hh | G13: M$ Lic. | H13: % M$ | K13: STATUS (a la fecha) | L13: Can. | M13: % | N13: hh Lic. | O13: % hh | P13: M$ Lic. | Q13: % M$ | T13: STATUS (a la fecha) | U13: Can. | V13: % | W13: hh Lic. | X13: % hh | Y13: M$ Lic. | Z13: % M$ | AU13: 2019 | AV13: 86458
B14: Totales | C14: =SUM(C15:C19) -> 50 | D14: =SUM(D15:D19) -> 50.5 | E14: =SUM(E15:E19) -> 102632.51 | F14: =SUM(F15:F19) -> 1 | G14: =SUM(G15:G19) -> 4304.8254 | H14: =SUM(H15:H19) -> 1 | K14: Totales | L14: =SUM(L15:L19) -> 42 | M14: =SUM(M15:M19) -> 100 | N14: =SUM(N15:N19) -> 27932.507 | O14: =SUM(O15:O19) -> 39.26026 | P14: =SUM(P15:P19) -> 896.68687 | Q14: =SUM(Q15:Q19) -> 100 | T14: Totales | U14: =SUM(U15:U19) -> 8 | V14: =SUM(V15:V19) -> 100 | W14: =SUM(W15:W19) -> 74700 | X14: =SUM(X15:X19) -> 100 | Y14: =SUM(Y15:Y19) -> 3408.1385 | Z14: =SUM(Z15:Z19) -> 100 | AU14: 2020 | AV14: 68104
A15: PG | B15: Propuestas Ganadas | C15: =COUNTIFS(Ofertas!$T$2242:$T$2765,Indicadores!A15,Ofertas!$AG$2242:$AG$2765,$B$12) -> 25 | D15: =C15/$C$14 -> 0.5 | E15: =SUMIFS(Ofertas!$W$2242:$W$2765,Ofertas!$T$2242:$T$2765,Indicadores!A15,Ofertas!$AG$2242:$AG$2765,Indicadores!$B$12) -> 17137.507 | F15: =E15/$E$14 -> 0.16697933 | G15: =SUMIFS(Ofertas!$X$2242:$X$2765,Ofertas!$T$2242:$T$2765,Indicadores!A15,Ofertas!$AG$2242:$AG$2765,Indicadores!$B$12) -> 501.15986 | H15: =G15/$G$14 -> 0.11641816 | J15: PG | K15: Propuestas Ganadas | L15: =COUNTIFS(Ofertas!$T$2242:$T$2765,Indicadores!J15,Ofertas!$AG$2242:$AG$2765,$K$12,Ofertas!$L$2242:$L$2765,Indicadores!$L$12) -> 25 | M15: =L15/$L$14*100 -> 59.52381 | N15: =SUMIFS(Ofertas!$W$2242:$W$2765,Ofertas!$T$2242:$T$2765,Indicadores!J15,Ofertas!$AG$2242:$AG$2765,Indicadores!$K$12,Ofertas!$L$2242:$L$2765,Indicadores!$L$12) -> 17137.507 | O15: =N15/$N$14 -> 0.61353273 | P15: =SUMIFS(Ofertas!$X$2242:$X$2765,Ofertas!$T$2242:$T$2765,Indicadores!J15,Ofertas!$AG$2242:$AG$2765,Indicadores!$K$12,Ofertas!$L$2242:$L$2765,Indicadores!$L$12) -> 501.15986 | Q15: =P15/$P$14*100 -> 55.890175 | S15: PG | T15: Propuestas Ganadas | U15: =COUNTIFS(Ofertas!$T$2242:$T$2765,Indicadores!S15,Ofertas!$AG$2242:$AG$2765,$T$12,Ofertas!$L$2242:$L$2765,Indicadores!$U$12) -> 0 | V15: =U15/$U$14*100 -> 0 | W15: =SUMIFS(Ofertas!$W$2242:$W$2765,Ofertas!$T$2242:$T$2765,Indicadores!S15,Ofertas!$AG$2242:$AG$2765,Indicadores!$T$12,Ofertas!$L$2242:$L$2765,Indicadores!$U$12) -> 0 | X15: =W15/$W$14 -> 0 | Y15: =SUMIFS(Ofertas!$X$2242:$X$2765,Ofertas!$T$2242:$T$2765,Indicadores!S15,Ofertas!$AG$2242:$AG$2765,Indicadores!$T$12,Ofertas!$L$2242:$L$2765,Indicadores!$U$12) -> 0 | Z15: =Y15/$Y$14*100 -> 0 | AU15: 2021 | AV15: 60000
A16: PP | B16: Propuestas Perdidas | C16: =COUNTIFS(Ofertas!$T$2242:$T$2765,Indicadores!A16,Ofertas!$AG$2242:$AG$2765,$B$12) -> 25 | D16: =C16/$C$14*100 -> 50 | E16: =SUMIFS(Ofertas!$W$2242:$W$2765,Ofertas!$T$2242:$T$2765,Indicadores!A16,Ofertas!$AG$2242:$AG$2765,Indicadores!$B$12) -> 85495 | F16: =E16/$E$14 -> 0.83302067 | G16: =SUMIFS(Ofertas!$X$2242:$X$2765,Ofertas!$T$2242:$T$2765,Indicadores!A16,Ofertas!$AG$2242:$AG$2765,Indicadores!$B$12) -> 3803.6655 | H16: =G16/$G$14 -> 0.88358184 | J16: PP | K16: Propuestas Perdidas | L16: =COUNTIFS(Ofertas!$T$2242:$T$2765,Indicadores!J16,Ofertas!$AG$2242:$AG$2765,$K$12,Ofertas!$L$2242:$L$2765,Indicadores!$L$12) -> 17 | M16: =L16/$L$14*100 -> 40.47619 | N16: =SUMIFS(Ofertas!$W$2242:$W$2765,Ofertas!$T$2242:$T$2765,Indicadores!J16,Ofertas!$AG$2242:$AG$2765,Indicadores!$K$12,Ofertas!$L$2242:$L$2765,Indicadores!$L$12) -> 10795 | O16: =N16/$N$14*100 -> 38.646727 | P16: =SUMIFS(Ofertas!$X$2242:$X$2765,Ofertas!$T$2242:$T$2765,Indicadores!J16,Ofertas!$AG$2242:$AG$2765,Indicadores!$K$12,Ofertas!$L$2242:$L$2765,Indicadores!$L$12) -> 395.52701 | Q16: =P16/$P$14*100 -> 44.109825 | S16: PP | T16: Propuestas Perdidas | U16: =COUNTIFS(Ofertas!$T$2242:$T$2765,Indicadores!S16,Ofertas!$AG$2242:$AG$2765,$T$12,Ofertas!$L$2242:$L$2765,Indicadores!$U$12) -> 8 | V16: =U16/$U$14*100 -> 100 | W16: =SUMIFS(Ofertas!$W$2242:$W$2765,Ofertas!$T$2242:$T$2765,Indicadores!S16,Ofertas!$AG$2242:$AG$2765,Indicadores!$T$12,Ofertas!$L$2242:$L$2765,Indicadores!$U$12) -> 74700 | X16: =W16/$W$14*100 -> 100 | Y16: =SUMIFS(Ofertas!$X$2242:$X$2765,Ofertas!$T$2242:$T$2765,Indicadores!S16,Ofertas!$AG$2242:$AG$2765,Indicadores!$T$12,Ofertas!$L$2242:$L$2765,Indicadores!$U$12) -> 3408.1385 | Z16: =Y16/$Y$14*100 -> 100
A17: PD | B17: Propuestas Desiertas | C17: =COUNTIFS(Ofertas!$T$2242:$T$2765,Indicadores!A17,Ofertas!$AG$2242:$AG$2765,$B$12) -> 0 | D17: =C17/$C$14*100 -> 0 | E17: =SUMIFS(Ofertas!$W$2242:$W$2765,Ofertas!$T$2242:$T$2765,Indicadores!A17,Ofertas!$AG$2242:$AG$2765,Indicadores!$B$12) -> 0 | F17: =E17/$E$5*100 -> 0 | G17: =SUMIFS(Ofertas!$X$2242:$X$2765,Ofertas!$T$2242:$T$2765,Indicadores!A17,Ofertas!$AG$2242:$AG$2765,Indicadores!$B$12) -> 0 | H17: =G17/$G$5*100 -> 0 | J17: PD | K17: Propuestas Desiertas | L17: =COUNTIFS(Ofertas!$T$2242:$T$2765,Indicadores!J17,Ofertas!$AG$2242:$AG$2765,$K$12,Ofertas!$L$2242:$L$2765,Indicadores!$L$12) -> 0 | M17: =L17/$L$14*100 -> 0 | N17: =SUMIFS(Ofertas!$W$2242:$W$2765,Ofertas!$T$2242:$T$2765,Indicadores!J17,Ofertas!$AG$2242:$AG$2765,Indicadores!$K$12,Ofertas!$L$2242:$L$2765,Indicadores!$L$12) -> 0 | O17: =N17/$N$14*100 -> 0 | P17: =SUMIFS(Ofertas!$X$2242:$X$2765,Ofertas!$T$2242:$T$2765,Indicadores!J17,Ofertas!$AG$2242:$AG$2765,Indicadores!$K$12,Ofertas!$L$2242:$L$2765,Indicadores!$L$12) -> 0 | Q17: =P17/$P$14*100 -> 0 | S17: PD | T17: Propuestas Desiertas | U17: =COUNTIFS(Ofertas!$T$2242:$T$2765,Indicadores!S17,Ofertas!$AG$2242:$AG$2765,$T$12,Ofertas!$L$2242:$L$2765,Indicadores!$U$12) -> 0 | V17: =U17/$U$14*100 -> 0 | W17: =SUMIFS(Ofertas!$W$2242:$W$2765,Ofertas!$T$2242:$T$2765,Indicadores!S17,Ofertas!$AG$2242:$AG$2765,Indicadores!$T$12,Ofertas!$L$2242:$L$2765,Indicadores!$U$12) -> 0 | X17: =W17/$W$14*100 -> 0 | Y17: =SUMIFS(Ofertas!$X$2242:$X$2765,Ofertas!$T$2242:$T$2765,Indicadores!S17,Ofertas!$AG$2242:$AG$2765,Indicadores!$T$12,Ofertas!$L$2242:$L$2765,Indicadores!$U$12) -> 0 | Z17: =Y17/$Y$14*100 -> 0
A18: DP | B18: Decisión del Cliente Pendiente | C18: =COUNTIFS(Ofertas!$T$2242:$T$2765,Indicadores!A18,Ofertas!$AG$2242:$AG$2765,$B$12) -> 0 | D18: =C18/$C$14*100 -> 0 | E18: =SUMIFS(Ofertas!$W$2242:$W$2765,Ofertas!$T$2242:$T$2765,Indicadores!A18,Ofertas!$AG$2242:$AG$2765,Indicadores!$B$12) -> 0 | F18: =E18/$E$5*100 -> 0 | G18: =SUMIFS(Ofertas!$X$2242:$X$2765,Ofertas!$T$2242:$T$2765,Indicadores!A18,Ofertas!$AG$2242:$AG$2765,Indicadores!$B$12) -> 0 | H18: =G18/$G$5*100 -> 0 | J18: DP | K18: Decisión del Cliente Pendiente | L18: =COUNTIFS(Ofertas!$T$2242:$T$2765,Indicadores!J18,Ofertas!$AG$2242:$AG$2765,$K$12,Ofertas!$L$2242:$L$2765,Indicadores!$L$12) -> 0 | M18: =L18/$L$14*100 -> 0 | N18: =SUMIFS(Ofertas!$W$2242:$W$2765,Ofertas!$T$2242:$T$2765,Indicadores!J18,Ofertas!$AG$2242:$AG$2765,Indicadores!$K$12,Ofertas!$L$2242:$L$2765,Indicadores!$L$12) -> 0 | O18: =N18/$N$14*100 -> 0 | P18: =SUMIFS(Ofertas!$X$2242:$X$2765,Ofertas!$T$2242:$T$2765,Indicadores!J18,Ofertas!$AG$2242:$AG$2765,Indicadores!$K$12,Ofertas!$L$2242:$L$2765,Indicadores!$L$12) -> 0 | Q18: =P18/$P$14*100 -> 0 | S18: DP | T18: Decisión del Cliente Pendiente | U18: =COUNTIFS(Ofertas!$T$2242:$T$2765,Indicadores!S18,Ofertas!$AG$2242:$AG$2765,$T$12,Ofertas!$L$2242:$L$2765,Indicadores!$U$12) -> 0 | V18: =U18/$U$14*100 -> 0 | W18: =SUMIFS(Ofertas!$W$2242:$W$2765,Ofertas!$T$2242:$T$2765,Indicadores!S18,Ofertas!$AG$2242:$AG$2765,Indicadores!$T$12,Ofertas!$L$2242:$L$2765,Indicadores!$U$12) -> 0 | X18: =W18/$W$14*100 -> 0 | Y18: =SUMIFS(Ofertas!$X$2242:$X$2765,Ofertas!$T$2242:$T$2765,Indicadores!S18,Ofertas!$AG$2242:$AG$2765,Indicadores!$T$12,Ofertas!$L$2242:$L$2765,Indicadores!$U$12) -> 0 | Z18: =Y18/$Y$14*100 -> 0
A19: EP | B19: Propuestas en Preparación | C19: =COUNTIFS(Ofertas!$T$2242:$T$2765,Indicadores!A19,Ofertas!$AG$2242:$AG$2765,$B$12) -> 0 | D19: =C19/$C$14*100 -> 0 | E19: =SUMIFS(Ofertas!$W$2242:$W$2765,Ofertas!$T$2242:$T$2765,Indicadores!A19,Ofertas!$AG$2242:$AG$2765,Indicadores!$B$12) -> 0 | F19: =E19/$E$5*100 -> 0 | G19: =SUMIFS(Ofertas!$X$2242:$X$2765,Ofertas!$T$2242:$T$2765,Indicadores!A19,Ofertas!$AG$2242:$AG$2765,Indicadores!$B$12) -> 0 | H19: =G19/$G$5*100 -> 0 | J19: EP | K19: Propuestas en Preparación | L19: =COUNTIFS(Ofertas!$T$2242:$T$2765,Indicadores!J19,Ofertas!$AG$2242:$AG$2765,$K$12,Ofertas!$L$2242:$L$2765,Indicadores!$L$12) -> 0 | M19: =L19/$L$14*100 -> 0 | N19: =SUMIFS(Ofertas!$W$2242:$W$2765,Ofertas!$T$2242:$T$2765,Indicadores!J19,Ofertas!$AG$2242:$AG$2765,Indicadores!$K$12,Ofertas!$L$2242:$L$2765,Indicadores!$L$12) -> 0 | O19: =N19/$N$14*100 -> 0 | P19: =SUMIFS(Ofertas!$X$2242:$X$2765,Ofertas!$T$2242:$T$2765,Indicadores!J19,Ofertas!$AG$2242:$AG$2765,Indicadores!$K$12,Ofertas!$L$2242:$L$2765,Indicadores!$L$12) -> 0 | Q19: =P19/$P$14*100 -> 0 | S19: EP | T19: Propuestas en Preparación | U19: =COUNTIFS(Ofertas!$T$2242:$T$2765,Indicadores!S19,Ofertas!$AG$2242:$AG$2765,$T$12,Ofertas!$L$2242:$L$2765,Indicadores!$U$12) -> 0 | V19: =U19/$U$14*100 -> 0 | W19: =SUMIFS(Ofertas!$W$2242:$W$2765,Ofertas!$T$2242:$T$2765,Indicadores!S19,Ofertas!$AG$2242:$AG$2765,Indicadores!$T$12,Ofertas!$L$2242:$L$2765,Indicadores!$U$12) -> 0 | X19: =W19/$W$14*100 -> 0 | Y19: =SUMIFS(Ofertas!$X$2242:$X$2765,Ofertas!$T$2242:$T$2765,Indicadores!S19,Ofertas!$AG$2242:$AG$2765,Indicadores!$T$12,Ofertas!$L$2242:$L$2765,Indicadores!$U$12) -> 0 | Z19: =Y19/$Y$14*100 -> 0
B21: 2012 | K21: 2012 | L21: ND | M21: NEGOCIACIÓN DIRECTA | T21: 2012 | U21: LM | V21: LICITACIÓN MÚLTIPLE
B22: STATUS (a la fecha) | C22: Can. | D22: % | E22: hh Lic. | F22: % hh | G22: M$ Lic. | H22: % M$ | K22: STATUS (a la fecha) | L22: Can. | M22: % | N22: hh Lic. | O22: % hh | P22: M$ Lic. | Q22: % M$ | T22: STATUS (a la fecha) | U22: Can. | V22: % | W22: hh Lic. | X22: % hh | Y22: M$ Lic. | Z22: % M$
B23: Totales | C23: =SUM(C24:C28) -> 60 | D23: =SUM(D24:D28) -> 1 | E23: =SUM(E24:E28) -> 128917.5 | F23: =SUM(F24:F28) -> 1 | G23: =SUM(G24:G28) -> 4372.6884 | H23: =SUM(H24:H28) -> 1 | K23: Totales | L23: =SUM(L24:L28) -> 52 | M23: =SUM(M24:M28) -> 100 | N23: =SUM(N24:N28) -> 92328.5 | O23: =SUM(O24:O28) -> 78.759099 | P23: =SUM(P24:P28) -> 3334.8189 | Q23: =SUM(Q24:Q28) -> 100 | T23: Totales | U23: =SUM(U24:U28) -> 8 | V23: =SUM(V24:V28) -> 100 | W23: =SUM(W24:W28) -> 36589 | X23: =SUM(X24:X28) -> 98.308918 | Y23: =SUM(Y24:Y28) -> 1037.8695 | Z23: =SUM(Z24:Z28) -> 100
A24: PG | B24: Propuestas Ganadas | C24: =COUNTIFS(Ofertas!$T$2242:$T$2765,Indicadores!A24,Ofertas!$AG$2242:$AG$2765,$B$21) -> 23 | D24: =C24/$C$23 -> 0.38333333 | E24: =SUMIFS(Ofertas!$W$2242:$W$2765,Ofertas!$T$2242:$T$2765,Indicadores!A24,Ofertas!$AG$2242:$AG$2765,Indicadores!$B$21) -> 20434.5 | F24: =E24/$E$23 -> 0.15850835 | G24: =SUMIFS(Ofertas!$X$2242:$X$2765,Ofertas!$T$2242:$T$2765,Indicadores!A24,Ofertas!$AG$2242:$AG$2765,Indicadores!$B$21) -> 668.23613 | H24: =G24/$G$23 -> 0.15282043 | J24: PG | K24: Propuestas Ganadas | L24: =COUNTIFS(Ofertas!$T$2242:$T$2765,Indicadores!J24,Ofertas!$AG$2242:$AG$2765,$K$21,Ofertas!$L$2242:$L$2765,Indicadores!$L$21) -> 22 | M24: =L24/$L$23*100 -> 42.307692 | N24: =SUMIFS(Ofertas!$W$2242:$W$2765,Ofertas!$T$2242:$T$2765,Indicadores!J24,Ofertas!$AG$2242:$AG$2765,Indicadores!$K$21,Ofertas!$L$2242:$L$2765,Indicadores!$L$21) -> 19809.5 | O24: =N24/$N$23 -> 0.21455455 | P24: =SUMIFS(Ofertas!$X$2242:$X$2765,Ofertas!$T$2242:$T$2765,Indicadores!J24,Ofertas!$AG$2242:$AG$2765,Indicadores!$K$21,Ofertas!$L$2242:$L$2765,Indicadores!$L$21) -> 641.43863 | Q24: =P24/$P$23*100 -> 19.234586 | S24: PG | T24: Propuestas Ganadas | U24: =COUNTIFS(Ofertas!$T$2242:$T$2765,Indicadores!S24,Ofertas!$AG$2242:$AG$2765,$T$21,Ofertas!$L$2242:$L$2765,Indicadores!$U$21) -> 1 | V24: =U24/$U$23*100 -> 12.5 | W24: =SUMIFS(Ofertas!$W$2242:$W$2765,Ofertas!$T$2242:$T$2765,Indicadores!S24,Ofertas!$AG$2242:$AG$2765,Indicadores!$T$21,Ofertas!$L$2242:$L$2765,Indicadores!$U$21) -> 625 | X24: =W24/$W$23 -> 0.017081637 | Y24: =SUMIFS(Ofertas!$X$2242:$X$2765,Ofertas!$T$2242:$T$2765,Indicadores!S24,Ofertas!$AG$2242:$AG$2765,Indicadores!$T$21,Ofertas!$L$2242:$L$2765,Indicadores!$U$21) -> 26.7975 | Z24: =Y24/$Y$23*100 -> 2.581972
A25: PP | B25: Propuestas Perdidas | C25: =COUNTIFS(Ofertas!$T$2242:$T$2765,Indicadores!A25,Ofertas!$AG$2242:$AG$2765,$B$21) -> 37 | D25: =C25/$C$23 -> 0.61666667 | E25: =SUMIFS(Ofertas!$W$2242:$W$2765,Ofertas!$T$2242:$T$2765,Indicadores!A25,Ofertas!$AG$2242:$AG$2765,Indicadores!$B$21) -> 108483 | F25: =E25/$E$23 -> 0.84149165 | G25: =SUMIFS(Ofertas!$X$2242:$X$2765,Ofertas!$T$2242:$T$2765,Indicadores!A25,Ofertas!$AG$2242:$AG$2765,Indicadores!$B$21) -> 3704.4523 | H25: =G25/$G$23 -> 0.84717957 | J25: PP | K25: Propuestas Perdidas | L25: =COUNTIFS(Ofertas!$T$2242:$T$2765,Indicadores!J25,Ofertas!$AG$2242:$AG$2765,$K$21,Ofertas!$L$2242:$L$2765,Indicadores!$L$21) -> 30 | M25: =L25/$L$23*100 -> 57.692308 | N25: =SUMIFS(Ofertas!$W$2242:$W$2765,Ofertas!$T$2242:$T$2765,Indicadores!J25,Ofertas!$AG$2242:$AG$2765,Indicadores!$K$21,Ofertas!$L$2242:$L$2765,Indicadores!$L$21) -> 72519 | O25: =N25/$N$23*100 -> 78.544545 | P25: =SUMIFS(Ofertas!$X$2242:$X$2765,Ofertas!$T$2242:$T$2765,Indicadores!J25,Ofertas!$AG$2242:$AG$2765,Indicadores!$K$21,Ofertas!$L$2242:$L$2765,Indicadores!$L$21) -> 2693.3803 | Q25: =P25/$P$23*100 -> 80.765414 | S25: PP | T25: Propuestas Perdidas | U25: =COUNTIFS(Ofertas!$T$2242:$T$2765,Indicadores!S25,Ofertas!$AG$2242:$AG$2765,$T$21,Ofertas!$L$2242:$L$2765,Indicadores!$U$21) -> 7 | V25: =U25/$U$23*100 -> 87.5 | W25: =SUMIFS(Ofertas!$W$2242:$W$2765,Ofertas!$T$2242:$T$2765,Indicadores!S25,Ofertas!$AG$2242:$AG$2765,Indicadores!$T$21,Ofertas!$L$2242:$L$2765,Indicadores!$U$21) -> 35964 | X25: =W25/$W$23*100 -> 98.291836 | Y25: =SUMIFS(Ofertas!$X$2242:$X$2765,Ofertas!$T$2242:$T$2765,Indicadores!S25,Ofertas!$AG$2242:$AG$2765,Indicadores!$T$21,Ofertas!$L$2242:$L$2765,Indicadores!$U$21) -> 1011.072 | Z25: =Y25/$Y$23*100 -> 97.418028
A26: PD | B26: Propuestas Desiertas | C26: =COUNTIFS(Ofertas!$T$2242:$T$2765,Indicadores!A26,Ofertas!$AG$2242:$AG$2765,$B$21) -> 0 | D26: =C26/$C$23 -> 0 | E26: =SUMIFS(Ofertas!$W$2242:$W$2765,Ofertas!$T$2242:$T$2765,Indicadores!A26,Ofertas!$AG$2242:$AG$2765,Indicadores!$B$21) -> 0 | F26: =E26/$E$23 -> 0 | G26: =SUMIFS(Ofertas!$X$2242:$X$2765,Ofertas!$T$2242:$T$2765,Indicadores!A26,Ofertas!$AG$2242:$AG$2765,Indicadores!$B$21) -> 0 | H26: =G26/$G$23 -> 0 | J26: PD | K26: Propuestas Desiertas | L26: =COUNTIFS(Ofertas!$T$2242:$T$2765,Indicadores!J26,Ofertas!$AG$2242:$AG$2765,$K$21,Ofertas!$L$2242:$L$2765,Indicadores!$L$21) -> 0 | M26: =L26/$L$23*100 -> 0 | N26: =SUMIFS(Ofertas!$W$2242:$W$2765,Ofertas!$T$2242:$T$2765,Indicadores!J26,Ofertas!$AG$2242:$AG$2765,Indicadores!$K$21,Ofertas!$L$2242:$L$2765,Indicadores!$L$21) -> 0 | O26: =N26/$N$23*100 -> 0 | P26: =SUMIFS(Ofertas!$X$2242:$X$2765,Ofertas!$T$2242:$T$2765,Indicadores!J26,Ofertas!$AG$2242:$AG$2765,Indicadores!$K$21,Ofertas!$L$2242:$L$2765,Indicadores!$L$21) -> 0 | Q26: =P26/$P$23*100 -> 0 | S26: PD | T26: Propuestas Desiertas | U26: =COUNTIFS(Ofertas!$T$2242:$T$2765,Indicadores!S26,Ofertas!$AG$2242:$AG$2765,$T$21,Ofertas!$L$2242:$L$2765,Indicadores!$U$21) -> 0 | V26: =U26/$U$23*100 -> 0 | W26: =SUMIFS(Ofertas!$W$2242:$W$2765,Ofertas!$T$2242:$T$2765,Indicadores!S26,Ofertas!$AG$2242:$AG$2765,Indicadores!$T$21,Ofertas!$L$2242:$L$2765,Indicadores!$U$21) -> 0 | X26: =W26/$W$23*100 -> 0 | Y26: =SUMIFS(Ofertas!$X$2242:$X$2765,Ofertas!$T$2242:$T$2765,Indicadores!S26,Ofertas!$AG$2242:$AG$2765,Indicadores!$T$21,Ofertas!$L$2242:$L$2765,Indicadores!$U$21) -> 0 | Z26: =Y26/$Y$23*100 -> 0
